Failure # 1 (occurred at 2023-08-19_13-26-36)
[36mray::PPO.train()[39m (pid=44118, ip=172.16.5.4, actor_id=63c1da02feeea6f57ef1b0d001000000, repr=PPO)
  File "/home/codespace/.python/current/lib/python3.10/site-packages/ray/tune/trainable/trainable.py", line 375, in train
    raise skipped from exception_cause(skipped)
  File "/home/codespace/.python/current/lib/python3.10/site-packages/ray/tune/trainable/trainable.py", line 372, in train
    result = self.step()
  File "/home/codespace/.python/current/lib/python3.10/site-packages/ray/rllib/algorithms/algorithm.py", line 851, in step
    results, train_iter_ctx = self._run_one_training_iteration()
  File "/home/codespace/.python/current/lib/python3.10/site-packages/ray/rllib/algorithms/algorithm.py", line 2835, in _run_one_training_iteration
    results = self.training_step()
  File "/home/codespace/.python/current/lib/python3.10/site-packages/ray/rllib/algorithms/ppo/ppo.py", line 429, in training_step
    train_batch = synchronous_parallel_sample(
  File "/home/codespace/.python/current/lib/python3.10/site-packages/ray/rllib/execution/rollout_ops.py", line 85, in synchronous_parallel_sample
    sample_batches = worker_set.foreach_worker(
  File "/home/codespace/.python/current/lib/python3.10/site-packages/ray/rllib/evaluation/worker_set.py", line 680, in foreach_worker
    handle_remote_call_result_errors(remote_results, self._ignore_worker_failures)
  File "/home/codespace/.python/current/lib/python3.10/site-packages/ray/rllib/evaluation/worker_set.py", line 76, in handle_remote_call_result_errors
    raise r.get()
ray.exceptions.RayTaskError(IndexError): [36mray::RolloutWorker.apply()[39m (pid=44183, ip=172.16.5.4, actor_id=5e29607cb3a4e7a7fc6a85e101000000, repr=<ray.rllib.evaluation.rollout_worker.RolloutWorker object at 0x7f97c6c74400>)
  File "/home/codespace/.python/current/lib/python3.10/site-packages/ray/rllib/utils/actor_manager.py", line 185, in apply
    raise e
  File "/home/codespace/.python/current/lib/python3.10/site-packages/ray/rllib/utils/actor_manager.py", line 176, in apply
    return func(self, *args, **kwargs)
  File "/home/codespace/.python/current/lib/python3.10/site-packages/ray/rllib/execution/rollout_ops.py", line 86, in <lambda>
    lambda w: w.sample(), local_worker=False, healthy_only=True
  File "/home/codespace/.python/current/lib/python3.10/site-packages/ray/rllib/evaluation/rollout_worker.py", line 696, in sample
    batches = [self.input_reader.next()]
  File "/home/codespace/.python/current/lib/python3.10/site-packages/ray/rllib/evaluation/sampler.py", line 92, in next
    batches = [self.get_data()]
  File "/home/codespace/.python/current/lib/python3.10/site-packages/ray/rllib/evaluation/sampler.py", line 277, in get_data
    item = next(self._env_runner)
  File "/home/codespace/.python/current/lib/python3.10/site-packages/ray/rllib/evaluation/env_runner_v2.py", line 344, in run
    outputs = self.step()
  File "/home/codespace/.python/current/lib/python3.10/site-packages/ray/rllib/evaluation/env_runner_v2.py", line 400, in step
    self._base_env.send_actions(actions_to_send)
  File "/home/codespace/.python/current/lib/python3.10/site-packages/ray/rllib/env/vector_env.py", line 464, in send_actions
    ) = self.vector_env.vector_step(action_vector)
  File "/home/codespace/.python/current/lib/python3.10/site-packages/ray/rllib/env/vector_env.py", line 360, in vector_step
    raise e
  File "/home/codespace/.python/current/lib/python3.10/site-packages/ray/rllib/env/vector_env.py", line 353, in vector_step
    results = self.envs[i].step(actions[i])
  File "/tmp/ipykernel_42515/1497064064.py", line 261, in step
  File "/tmp/ipykernel_42515/1497064064.py", line 139, in first
IndexError: only integers, slices (`:`), ellipsis (`...`), numpy.newaxis (`None`) and integer or boolean arrays are valid indices
